<?xml version='1.0'?>
<sdf version='1.10'>
  <model name="tugbot">
    <pose>0 0 0.2 0 0 0</pose>
    <static>false</static>
    <self_collide>false</self_collide>

    <link name="base_link">
      <pose>0 0 0 0 0 0</pose>
      <inertial>
        <pose>-0.1 0 0.1 0 0 0</pose>
        <mass>46.2</mass>
        <inertia>
          <ixx>1.55925</ixx>
          <ixy>0</ixy>
          <ixz>0</ixz>
          <iyy>1.55925</iyy>
          <iyz>0</iyz>
          <izz>1.55925</izz>
        </inertia>
      </inertial>
      <collision name="base_link_collision">
        <geometry>
          <mesh>
            <uri>meshes/base/tugbot_simp.stl</uri>
          </mesh>
        </geometry>
      </collision>
      <visual name="base_link_visual">
        <geometry>
          <mesh>
            <uri>meshes/base/tugbot_simp.dae</uri>
          </mesh>
        </geometry>
      </visual>
      <visual name="movai_logo_visual">
        <pose>0 0 0 0 0 0</pose>
        <geometry>
          <mesh>
            <uri>meshes/base/movai_logo.dae</uri>
          </mesh>
        </geometry>
        <material>
          <diffuse>1.0 1.0 1.0 1.0</diffuse>
          <pbr>
            <metal>
              <albedo_map>meshes/base/movai-logo.png</albedo_map>
            </metal>
          </pbr>
        </material>
      </visual>
      <visual name="beacon_led_visual">
        <pose>-0.1 0 0.1945 0 1.57079632679 0</pose>
        <geometry>
          <mesh>
            <scale>1.0 1.0 1.0</scale>
            <uri>meshes/light_link/light_led.stl</uri>
          </mesh>
        </geometry>
        <material>
          <ambient>0.0 0.0 0 1</ambient>
          <diffuse>0.0 0.0 0 1</diffuse>
          <specular>0 0 0 1</specular>
          <emissive>0 1 0 1</emissive>
        </material>
      </visual>
      <visual name="beacon_cover_visual">
        <pose>-0.099 0 0.195 0 1.57079632679 0</pose>
        <geometry>
          <mesh>
            <scale>1.02 1.02 1.02</scale>
            <uri>meshes/light_link/light.stl</uri>
          </mesh>
        </geometry>
        <material>
          <ambient>0.1 0.05 0 0.5</ambient>
          <diffuse>1 0.5 0 0.5</diffuse>
          <specular>1 0.5 0 0.5</specular>
          <emissive>1 0.5 0 0.5</emissive>
        </material>
      </visual>
      <visual name="top_lidar_base_cylinder_visual">
        <pose>-0.1855 0 0.4968 0 0 0</pose>
        <geometry>
          <cylinder>
            <radius>0.06</radius>
            <length>0.0015</length>
          </cylinder>
        </geometry>
      </visual>
      <visual name="top_lidar_support_1_visual">
        <pose>-0.2205 0.035 0.4518 0 0 0</pose>
        <geometry>
          <cylinder>
            <radius>0.005</radius>
            <length>0.09</length>
          </cylinder>
        </geometry>
      </visual>
      <visual name="top_lidar_support_2_visual">
        <pose>-0.2205 -0.035 0.4518 0 0 0</pose>
        <geometry>
          <cylinder>
            <radius>0.005</radius>
            <length>0.09</length>
          </cylinder>
        </geometry>
      </visual>
      <visual name="top_lidar_support_3_visual">
        <pose>-0.136 0 0.4518 0 0 0</pose>
        <geometry>
          <cylinder>
            <radius>0.005</radius>
            <length>0.09</length>
          </cylinder>
        </geometry>
      </visual>
      <visual name="top_lidar_base_visual">
        <pose>-0.1855 0 0.4968 0 0 0</pose>
        <geometry>
          <mesh>
            <scale>1 1 1</scale>
            <uri>meshes/VLP16_base_1.dae</uri>
          </mesh>
        </geometry>
      </visual>
      <visual name="top_lidar_sensor_visual">
        <pose>-0.1855 0 0.4968 0 0 0</pose>
        <geometry>
          <mesh>
            <scale>1 1 1</scale>
            <uri>meshes/VLP16_base_2.dae</uri>
          </mesh>
        </geometry>
      </visual>
      <visual name="top_lidar_scan_visual">
        <pose>-0.1855 0 0.4968 0 0 0</pose>
        <geometry>
          <mesh>
            <scale>1 1 1</scale>
            <uri>meshes/VLP16_scan.dae</uri>
          </mesh>
        </geometry>
      </visual>
      <visual name="rear_gripper_visual">
        <pose>-0.35 0 0.1 -1.57079632679 0 0</pose>
        <geometry>
          <mesh>
            <scale>1 1 1</scale>
            <uri>meshes/gripper2/gripper2.dae</uri>
          </mesh>
        </geometry>
      </visual>
      <visual name="rear_gripper_hand_visual">
        <pose>-0.463 0 0.1 1.570796327 0 1.570796327</pose>
        <geometry>
          <mesh>
            <scale>0.001 0.001 0.001</scale>
            <uri>meshes/gripper2/gripper_hand.stl</uri>
          </mesh>
        </geometry>
        <material>
          <ambient>0.1 0.1 0.1 1</ambient>
          <diffuse>0.3 0.3 0.3 1</diffuse>
          <specular>1 1 1 1</specular>
          <emissive>0 0 0 1</emissive>
        </material>
      </visual>
    </link>

    <link name="camera_front">
      <pose relative_to="base_link">0.28 0 0.44 0 1.05 0</pose>
      <inertial>
        <mass>0.2</mass>
        <inertia>
          <ixx>0.0005</ixx>
          <ixy>0</ixy>
          <ixz>0</ixz>
          <iyy>0.0005</iyy>
          <iyz>0</iyz>
          <izz>0.0005</izz>
        </inertia>
      </inertial>
      <collision name="camera_front_collision">
        <geometry>
          <box>
            <size>0.05 0.05 0.05</size>
          </box>
        </geometry>
      </collision>
      <visual name="camera_front_visual">
        <material>
          <ambient>0.1 0.1 0.1 1</ambient>
          <diffuse>0.1 0.1 0.1 1</diffuse>
        </material>
        <geometry>
          <box>
            <size>0.05 0.05 0.05</size>
          </box>
        </geometry>
      </visual>
      <sensor name="camera_front_sensor" type="camera">
        <pose>0 0 0 0 0 0</pose>
        <topic>/camera/image_raw</topic>
        <update_rate>15</update_rate>
        <always_on>1</always_on>
        <visualize>true</visualize>
        <camera>
          <horizontal_fov>1.20427718</horizontal_fov>
          <image>
            <width>640</width>
            <height>360</height>
            <format>R8G8B8</format>
          </image>
          <camera_info_topic>/camera/camera_info</camera_info_topic>
          <clip>
            <near>0.05</near>
            <far>30</far>
          </clip>
        </camera>
      </sensor>
    </link>

    <joint name="camera_front_joint" type="fixed">
      <parent>base_link</parent>
      <child>camera_front</child>
    </joint>

    <link name="wheel_front">
      <pose>0.145 0 0.0345 1.570796327 0 0</pose>
      <inertial>
        <mass>0.1</mass>
        <inertia>
          <ixx>0.0000175</ixx>
          <ixy>0</ixy>
          <ixz>0</ixz>
          <iyy>0.0000175</iyy>
          <iyz>0</iyz>
          <izz>0.0000175</izz>
        </inertia>
      </inertial>
      <collision name="wheel_front_collision">
        <geometry><sphere><radius>0.025</radius></sphere></geometry>
      </collision>
    </link>

    <joint name="wheel_front_joint" type="ball">
      <child>wheel_front</child>
      <parent>base_link</parent>
    </joint>

    <link name="wheel_back">
      <pose>-0.225 0 0.035 1.570796327 0 0</pose>
      <inertial>
        <mass>0.1</mass>
        <inertia>
          <ixx>0.0000175</ixx>
          <ixy>0</ixy>
          <ixz>0</ixz>
          <iyy>0.0000175</iyy>
          <iyz>0</iyz>
          <izz>0.0000175</izz>
        </inertia>
      </inertial>
      <collision name="wheel_back_collision">
        <geometry><sphere><radius>0.035</radius></sphere></geometry>
      </collision>
    </link>

    <joint name="wheel_back_joint" type="ball">
      <child>wheel_back</child>
      <parent>base_link</parent>
    </joint>

    <link name="wheel_left">
      <pose>0 0.257 0.195 -1.570796327 0 0</pose>
      <inertial>
        <mass>0.1</mass>
        <inertia>
          <ixx>0.0000175</ixx>
          <ixy>0</ixy>
          <ixz>0</ixz>
          <iyy>0.0000175</iyy>
          <iyz>0</iyz>
          <izz>0.00003125</izz>
        </inertia>
      </inertial>
      <collision name="wheel_left_collision">
        <geometry><cylinder><radius>0.195</radius><length>0.05</length></cylinder></geometry>
      </collision>
      <visual name="wheel_left_visual">
        <pose>0 0 -0.03 0 0 0</pose>
        <geometry>
          <mesh>
            <scale>0.98 0.98 1.0</scale>
            <uri>meshes/wheel/wheel.dae</uri>
          </mesh>
        </geometry>
      </visual>
    </link>

    <joint name="wheel_left_joint" type="revolute">
      <child>wheel_left</child>
      <parent>base_link</parent>
      <axis>
        <xyz>0 0 1</xyz>
        <limit><effort>9.6</effort></limit>
        <dynamics><damping>3.0</damping><friction>0.5</friction></dynamics>
      </axis>
    </joint>

    <link name="wheel_right">
      <pose>0 -0.257 0.195 1.570796327 0 0</pose>
      <inertial>
        <mass>0.1</mass>
        <inertia>
          <ixx>0.0000175</ixx>
          <ixy>0</ixy>
          <ixz>0</ixz>
          <iyy>0.0000175</iyy>
          <iyz>0</iyz>
          <izz>0.00003125</izz>
        </inertia>
      </inertial>
      <collision name="wheel_right_collision">
        <geometry><cylinder><radius>0.195</radius><length>0.05</length></cylinder></geometry>
      </collision>
      <visual name="wheel_right_visual">
        <pose>0 0 -0.03 0 0 0</pose>
        <geometry>
          <mesh>
            <scale>0.98 0.98 1.0</scale>
            <uri>meshes/wheel/wheel.dae</uri>
          </mesh>
        </geometry>
      </visual>
    </link>

    <joint name="wheel_right_joint" type="revolute">
      <child>wheel_right</child>
      <parent>base_link</parent>
      <axis>
        <xyz>0 0 -1</xyz>
        <limit><effort>9.6</effort></limit>
        <dynamics><damping>3.0</damping><friction>0.5</friction></dynamics>
      </axis>
    </joint>

    <plugin filename="gz-sim-diff-drive-system" name="gz::sim::systems::DiffDrive">
      <left_joint>wheel_left_joint</left_joint>
      <right_joint>wheel_right_joint</right_joint>
      <wheel_separation>0.514</wheel_separation>
      <wheel_radius>0.195</wheel_radius>
      <min_velocity>-3.0</min_velocity>
      <max_velocity>3.0</max_velocity>
      <min_acceleration>-0.8</min_acceleration>
      <max_acceleration>0.8</max_acceleration>
      <odom_publish_frequency>10</odom_publish_frequency>
      <topic>/cmd_vel</topic>
    </plugin>

    <plugin filename="gz-sim-sensors-system" name="gz::sim::systems::Sensors">
      <render_engine>ogre2</render_engine>
    </plugin>
  </model>
</sdf>
