<?xml version='1.0' encoding='utf-8'?>
<sdf version="1.6">
  <model name="anymal_c">
    <link name="base">
      <pose>0 0 0 0 -0 0</pose>
      <gravity>false</gravity>
      <inertial>
        <pose>-0.02203 -0.000162 0.009216 0 -0 0</pose>
        <mass>29.23832</mass>
        <inertia>
          <ixx>0.236867</ixx>
          <ixy>0.00846724</ixy>
          <ixz>0.0854364</ixz>
          <iyy>2.06849</iyy>
          <iyz>-0.000253399</iyz>
          <izz>2.09006</izz>
        </inertia>
      </inertial>
      <visual name="base_visual">
        <pose>0 0 0 0 -0 0</pose>
        <geometry>
          <mesh>
            <scale>1 1 1</scale>
            <uri>meshes/base.dae</uri>
          </mesh>
        </geometry>
      </visual>
      <visual name="base_fixed_joint_lump__LF_HAA_visual_1">
        <pose>0.2999 0.104 0 2.61799 -0 0</pose>
        <geometry>
          <mesh>
            <scale>1 1 1</scale>
            <uri>meshes/drive.dae</uri>
          </mesh>
        </geometry>
      </visual>
      <visual name="base_fixed_joint_lump__LH_HAA_visual_2">
        <pose>-0.2999 0.104 0 -2.61799 -0 3.14159</pose>
        <geometry>
          <mesh>
            <scale>1 1 1</scale>
            <uri>meshes/drive.dae</uri>
          </mesh>
        </geometry>
      </visual>
      <visual name="base_fixed_joint_lump__RF_HAA_visual_3">
        <pose>0.2999 -0.104 0 -2.61799 0 0</pose>
        <geometry>
          <mesh>
            <scale>1 1 1</scale>
            <uri>meshes/drive.dae</uri>
          </mesh>
        </geometry>
      </visual>
      <visual name="base_fixed_joint_lump__RH_HAA_visual_4">
        <pose>-0.2999 -0.104 0 2.61799 0 3.14159</pose>
        <geometry>
          <mesh>
            <scale>1 1 1</scale>
            <uri>meshes/drive.dae</uri>
          </mesh>
        </geometry>
      </visual>
      <visual name="base_fixed_joint_lump__battery_visual_5">
        <pose>0 0 0 0 -0 0</pose>
        <geometry>
          <mesh>
            <scale>1 1 1</scale>
            <uri>meshes/battery.dae</uri>
          </mesh>
        </geometry>
      </visual>
      <visual name="base_fixed_joint_lump__bottom_shell_visual_6">
        <pose>0 0 0 0 -0 0</pose>
        <geometry>
          <mesh>
            <scale>1 1 1</scale>
            <uri>meshes/bottom_shell.dae</uri>
          </mesh>
        </geometry>
      </visual>
      <visual name="base_fixed_joint_lump__handle_visual_7">
        <pose>0 0 0 0 -0 0</pose>
        <geometry>
          <mesh>
            <scale>1 1 1</scale>
            <uri>meshes/handle.dae</uri>
          </mesh>
        </geometry>
      </visual>
      <visual name="base_fixed_joint_lump__hatch_visual_8">
        <pose>0.116 0 0.073 0 -0 0</pose>
        <geometry>
          <mesh>
            <scale>1 1 1</scale>
            <uri>meshes/hatch.dae</uri>
          </mesh>
        </geometry>
      </visual>
      <visual name="base_fixed_joint_lump__remote_visual_9">
        <pose>0 0 0 0 -0 0</pose>
        <geometry>
          <mesh>
            <scale>1 1 1</scale>
            <uri>meshes/remote.dae</uri>
          </mesh>
        </geometry>
      </visual>
      <visual name="base_fixed_joint_lump__alphasense_mesh_visual_10">
        <pose>-0.364 0 0 0 -0 0</pose>
        <geometry>
          <mesh>
            <scale>0.001 0.001 0.001</scale>
            <uri>meshes/alphasense.stl</uri>
          </mesh>
        </geometry>
        <material>
          <ambient>0.5 0.5 0.5 1</ambient>
          <diffuse>0.5 0.5 0.5 1</diffuse>
          <specular>0.5 0.5 0.5 1</specular>
        </material>
      </visual>
      <visual name="base_fixed_joint_lump__bpearl_front_visual_11">
        <pose>0.47 0 0.035 -2.85388 -0.54666 -0.517507</pose>
        <geometry>
          <mesh>
            <scale>0.001 0.001 0.001</scale>
            <uri>meshes/rslidar_bpearl.stl</uri>
          </mesh>
        </geometry>
        <material>
          <ambient>0.5 0.5 0.5 1</ambient>
          <diffuse>0.5 0.5 0.5 1</diffuse>
          <specular>0.5 0.5 0.5 1</specular>
        </material>
      </visual>
      <visual name="base_fixed_joint_lump__bpearl_front_protection_bars_visual_12">
        <pose>0.414495 0 0 0 0 -3.14159</pose>
        <geometry>
          <mesh>
            <scale>0.001 0.001 0.001</scale>
            <uri>meshes/bpearl_protection_bars.stl</uri>
          </mesh>
        </geometry>
        <material>
          <ambient>0.5 0.5 0.5 1</ambient>
          <diffuse>0.5 0.5 0.5 1</diffuse>
          <specular>0.5 0.5 0.5 1</specular>
        </material>
      </visual>
      <visual name="base_fixed_joint_lump__bpearl_rear_visual_13">
        <pose>-0.47 0 0.035 -2.85388 -0.54666 2.62409</pose>
        <geometry>
          <mesh>
            <scale>0.001 0.001 0.001</scale>
            <uri>meshes/rslidar_bpearl.stl</uri>
          </mesh>
        </geometry>
        <material>
          <ambient>0.5 0.5 0.5 1</ambient>
          <diffuse>0.5 0.5 0.5 1</diffuse>
          <specular>0.5 0.5 0.5 1</specular>
        </material>
      </visual>
      <visual name="base_fixed_joint_lump__bpearl_rear_protection_bars_visual_14">
        <pose>-0.414495 0 0 0 -0 0</pose>
        <geometry>
          <mesh>
            <scale>0.001 0.001 0.001</scale>
            <uri>meshes/bpearl_protection_bars.stl</uri>
          </mesh>
        </geometry>
        <material>
          <ambient>0.5 0.5 0.5 1</ambient>
          <diffuse>0.5 0.5 0.5 1</diffuse>
          <specular>0.5 0.5 0.5 1</specular>
        </material>
      </visual>
      <visual name="base_fixed_joint_lump__perception_head_cage_visual_15">
        <pose>-0.364 0 0 0 -0 0</pose>
        <geometry>
          <mesh>
            <scale>0.001 0.001 0.001</scale>
            <uri>meshes/perception_head.stl</uri>
          </mesh>
        </geometry>
        <material>
          <ambient>0.5 0.5 0.5 1</ambient>
          <diffuse>0.5 0.5 0.5 1</diffuse>
          <specular>0.5 0.5 0.5 1</specular>
        </material>
      </visual>
      <visual name="base_fixed_joint_lump__lidar_visual_16">
        <pose>-0.364 0 0.1422 0 0 -1.5708</pose>
        <geometry>
          <mesh>
            <scale>1 1 1</scale>
            <uri>meshes/lidar.dae</uri>
          </mesh>
        </geometry>
      </visual>
      <visual name="base_fixed_joint_lump__top_shell_visual_17">
        <pose>0 0 0 0 -0 0</pose>
        <geometry>
          <mesh>
            <scale>1 1 1</scale>
            <uri>meshes/top_shell.dae</uri>
          </mesh>
        </geometry>
      </visual>
      <visual name="base_fixed_joint_lump__imu_link_visual_18">
        <pose>0.2488 0.00835 0.05128 0 -0 1.5708</pose>
        <geometry>
          <box>
            <size>0.024 0.024 0.01</size>
          </box>
        </geometry>
      </visual>
      <!-- Sensors -->
      <sensor name="scan_omni" type="gpu_lidar">
        <pose>0 0 0.35 0 0 0</pose>
        <topic>/scan</topic>
        <always_on>1</always_on>
        <visualize>true</visualize>
        <update_rate>10</update_rate>
        <lidar>
          <scan>
            <horizontal>
              <samples>900</samples>
              <resolution>1</resolution>
              <min_angle>-3.141592654</min_angle>
              <max_angle>3.141592654</max_angle>
            </horizontal>
          </scan>
          <range>
            <min>0.2</min>
            <max>100.0</max>
            <resolution>0.01</resolution>
          </range>
        </lidar>
      </sensor>
      <!-- Lights -->
      <light name="light_up" type="spot">
        <pose frame="">-0.332 0.0 0.28 0.0 3.141 0.0</pose>
        <attenuation>
          <range>50</range>
          <linear>0</linear>
          <constant>0.1</constant>
          <quadratic>0.0025</quadratic>
        </attenuation>
        <diffuse>0.8 0.8 0.5 1</diffuse>
        <specular>0.8 0.8 0.5 1</specular>
        <spot>
          <inner_angle>1.2</inner_angle>
          <outer_angle>1.3</outer_angle>
          <falloff>1</falloff>
        </spot>
        <direction>0 0 1</direction>
      </light>
      <light name="light_forward" type="spot">
        <pose frame="">-0.41 0.0 0.265 0.0 1.57 0.0</pose>
        <attenuation>
          <range>50</range>
          <linear>0</linear>
          <constant>0.1</constant>
          <quadratic>0.0025</quadratic>
        </attenuation>
        <diffuse>0.8 0.8 0.5 1</diffuse>
        <specular>0.8 0.8 0.5 1</specular>
        <spot>
          <inner_angle>1.2</inner_angle>
          <outer_angle>1.3</outer_angle>
          <falloff>1</falloff>
        </spot>
        <direction>0 0 1</direction>
      </light>
      <light name="light_left" type="spot">
        <pose frame="">-0.348 -0.077 0.273 1.743 0.004 3.138</pose>
        <attenuation>
          <range>50</range>
          <linear>0</linear>
          <constant>0.1</constant>
          <quadratic>0.0025</quadratic>
        </attenuation>
        <diffuse>0.8 0.8 0.5 1</diffuse>
        <specular>0.8 0.8 0.5 1</specular>
        <spot>
          <inner_angle>1.2</inner_angle>
          <outer_angle>1.3</outer_angle>
          <falloff>1</falloff>
        </spot>
        <direction>0 0 1</direction>
      </light>
      <light name="light_right" type="spot">
        <pose frame="">-0.347 0.076 0.272 1.742 -0.011 -0.003</pose>
        <attenuation>
          <range>50</range>
          <linear>0</linear>
          <constant>0.1</constant>
          <quadratic>0.0025</quadratic>
        </attenuation>
        <diffuse>0.8 0.8 0.5 1</diffuse>
        <specular>0.8 0.8 0.5 1</specular>
        <spot>
          <inner_angle>1.2</inner_angle>
          <outer_angle>1.3</outer_angle>
          <falloff>1</falloff>
        </spot>
        <direction>0 0 1</direction>
      </light>
    </link>
    <link name="LF_HIP">
      <pose>0.2999 0.104 0 2.61799 -0 0</pose>
      <gravity>false</gravity>
      <inertial>
        <pose>0.056661 -0.015294 -0.008298 0 -0 0</pose>
        <mass>2.781</mass>
        <inertia>
          <ixx>0.00329553</ixx>
          <ixy>-1.03882e-05</ixy>
          <ixz>0.000107062</ixz>
          <iyy>0.00504435</iyy>
          <iyz>-0.000319492</iyz>
          <izz>0.0057269</izz>
        </inertia>
      </inertial>
      <visual name="LF_HIP_fixed_joint_lump__LF_hip_fixed_visual">
        <pose>0 0 0 -2.61799 0 0</pose>
        <geometry>
          <mesh>
            <scale>1 1 1</scale>
            <uri>meshes/hip_l.dae</uri>
          </mesh>
        </geometry>
      </visual>
      <visual name="LF_HIP_fixed_joint_lump__LF_HFE_visual_1">
        <pose>0.0599 -0.072582 -0.041905 -3.14159 0.523599 -1.5708</pose>
        <geometry>
          <mesh>
            <scale>1 1 1</scale>
            <uri>meshes/drive.dae</uri>
          </mesh>
        </geometry>
      </visual>
    </link>
    <joint name="LF_HAA" type="revolute">
      <child>LF_HIP</child>
      <parent>base</parent>
      <axis>
        <xyz>1 0 0</xyz>
        <limit>
          <lower>-0.72</lower>
          <upper>0.49</upper>
          <effort>80</effort>
          <velocity>7.5</velocity>
        </limit>
        <dynamics>
          <damping>0</damping>
          <friction>0</friction>
          <spring_reference>0</spring_reference>
          <spring_stiffness>0</spring_stiffness>
        </dynamics>
        <use_parent_model_frame>0</use_parent_model_frame>
      </axis>
    </joint>
    <link name="LF_THIGH">
      <pose>0.3598 0.18781 0 0 -0 1.5708</pose>
      <gravity>false</gravity>
      <inertial>
        <pose>0.030815 4.6e-05 -0.245696 0 -0 0</pose>
        <mass>3.071</mass>
        <inertia>
          <ixx>0.0295638</ixx>
          <ixy>4.42919e-05</ixy>
          <ixz>0.00414243</ixz>
          <iyy>0.029904</iyy>
          <iyz>9.448e-05</iyz>
          <izz>0.00486108</izz>
        </inertia>
      </inertial>
      <visual name="LF_THIGH_fixed_joint_lump__LF_thigh_fixed_visual">
        <pose>0 0 0 0 0 -1.5708</pose>
        <geometry>
          <mesh>
            <scale>1 1 1</scale>
            <uri>meshes/thigh.dae</uri>
          </mesh>
        </geometry>
      </visual>
      <visual name="LF_THIGH_fixed_joint_lump__LF_KFE_visual_1">
        <pose>0.1003 0 -0.285 0 -0 0</pose>
        <geometry>
          <mesh>
            <scale>1 1 1</scale>
            <uri>meshes/drive.dae</uri>
          </mesh>
        </geometry>
      </visual>
    </link>
    <joint name="LF_HFE" type="revolute">
      <child>LF_THIGH</child>
      <parent>LF_HIP</parent>
      <axis>
        <xyz>1 0 0</xyz>
        <limit>
          <lower>-9.42478</lower>
          <upper>9.42478</upper>
          <effort>80</effort>
          <velocity>7.5</velocity>
        </limit>
        <dynamics>
          <damping>0</damping>
          <friction>0</friction>
          <spring_reference>0</spring_reference>
          <spring_stiffness>0</spring_stiffness>
        </dynamics>
        <use_parent_model_frame>0</use_parent_model_frame>
      </axis>
    </joint>
    <link name="LF_SHANK">
      <pose>0.3598 0.28811 -0.285 0 -0 1.5708</pose>
      <gravity>false</gravity>
      <inertial>
        <pose>0.005462 -0.061253 -0.08066 0 -0 0</pose>
        <mass>0.58842</mass>
        <inertia>
          <ixx>0.0101611</ixx>
          <ixy>-5.35713e-05</ixy>
          <ixz>-2.26604e-05</ixz>
          <iyy>0.00881038</iyy>
          <iyz>-0.00181935</iyz>
          <izz>0.00154978</izz>
        </inertia>
      </inertial>
      <visual name="LF_SHANK_fixed_joint_lump__LF_shank_fixed_visual">
        <pose>0 0 0 0 0 -1.5708</pose>
        <geometry>
          <mesh>
            <scale>1 1 1</scale>
            <uri>meshes/shank_l.dae</uri>
          </mesh>
        </geometry>
      </visual>
      <visual name="LF_SHANK_fixed_joint_lump__LF_FOOT_visual_1">
        <pose>0.01305 -0.08795 -0.33797 0 0 -2.35619</pose>
        <geometry>
          <mesh>
            <scale>1 1 1</scale>
            <uri>meshes/foot.dae</uri>
          </mesh>
        </geometry>
      </visual>
    </link>
    <joint name="LF_KFE" type="revolute">
      <child>LF_SHANK</child>
      <parent>LF_THIGH</parent>
      <axis>
        <xyz>1 0 0</xyz>
        <limit>
          <lower>-9.42478</lower>
          <upper>9.42478</upper>
          <effort>80</effort>
          <velocity>7.5</velocity>
        </limit>
        <dynamics>
          <damping>0</damping>
          <friction>0</friction>
          <spring_reference>0</spring_reference>
          <spring_stiffness>0</spring_stiffness>
        </dynamics>
        <use_parent_model_frame>0</use_parent_model_frame>
      </axis>
    </joint>
    <link name="LH_HIP">
      <pose>-0.2999 0.104 0 -2.61799 -0 3.14159</pose>
      <gravity>false</gravity>
      <inertial>
        <pose>0.056763 0.015294 -0.008298 0 -0 0</pose>
        <mass>2.781</mass>
        <inertia>
          <ixx>0.00329553</ixx>
          <ixy>-1.10053e-05</ixy>
          <ixz>-0.000109121</ixz>
          <iyy>0.00504617</iyy>
          <iyz>0.000319492</iyz>
          <izz>0.00572872</izz>
        </inertia>
      </inertial>
      <visual name="LH_HIP_fixed_joint_lump__LH_hip_fixed_visual">
        <pose>0 0 0 2.61799 0 -0</pose>
        <geometry>
          <mesh>
            <scale>1 1 1</scale>
            <uri>meshes/hip_r.dae</uri>
          </mesh>
        </geometry>
      </visual>
      <visual name="LH_HIP_fixed_joint_lump__LH_HFE_visual_1">
        <pose>0.0599 0.072582 -0.041905 -3.14159 0.523599 1.5708</pose>
        <geometry>
          <mesh>
            <scale>1 1 1</scale>
            <uri>meshes/drive.dae</uri>
          </mesh>
        </geometry>
      </visual>
    </link>
    <joint name="LH_HAA" type="revolute">
      <child>LH_HIP</child>
      <parent>base</parent>
      <axis>
        <xyz>-1 0 0</xyz>
        <limit>
          <lower>-0.72</lower>
          <upper>0.49</upper>
          <effort>80</effort>
          <velocity>7.5</velocity>
        </limit>
        <dynamics>
          <damping>0</damping>
          <friction>0</friction>
          <spring_reference>0</spring_reference>
          <spring_stiffness>0</spring_stiffness>
        </dynamics>
        <use_parent_model_frame>0</use_parent_model_frame>
      </axis>
    </joint>
    <link name="LH_THIGH">
      <pose>-0.3598 0.18781 0 0 0 1.5708</pose>
      <gravity>false</gravity>
      <inertial>
        <pose>0.030815 4.6e-05 -0.245696 0 -0 0</pose>
        <mass>3.071</mass>
        <inertia>
          <ixx>0.0295638</ixx>
          <ixy>4.43959e-05</ixy>
          <ixz>0.00414243</ixz>
          <iyy>0.029904</iyy>
          <iyz>0.000114794</iyz>
          <izz>0.00486108</izz>
        </inertia>
      </inertial>
      <visual name="LH_THIGH_fixed_joint_lump__LH_thigh_fixed_visual">
        <pose>0 0 0 0 0 -1.5708</pose>
        <geometry>
          <mesh>
            <scale>1 1 1</scale>
            <uri>meshes/thigh.dae</uri>
          </mesh>
        </geometry>
      </visual>
      <visual name="LH_THIGH_fixed_joint_lump__LH_KFE_visual_1">
        <pose>0.1003 0 -0.285 0 -0 0</pose>
        <geometry>
          <mesh>
            <scale>1 1 1</scale>
            <uri>meshes/drive.dae</uri>
          </mesh>
        </geometry>
      </visual>
    </link>
    <joint name="LH_HFE" type="revolute">
      <child>LH_THIGH</child>
      <parent>LH_HIP</parent>
      <axis>
        <xyz>1 0 0</xyz>
        <limit>
          <lower>-9.42478</lower>
          <upper>9.42478</upper>
          <effort>80</effort>
          <velocity>7.5</velocity>
        </limit>
        <dynamics>
          <damping>0</damping>
          <friction>0</friction>
          <spring_reference>0</spring_reference>
          <spring_stiffness>0</spring_stiffness>
        </dynamics>
        <use_parent_model_frame>0</use_parent_model_frame>
      </axis>
    </joint>
    <link name="LH_SHANK">
      <pose>-0.3598 0.28811 -0.285 0 0 1.5708</pose>
      <gravity>false</gravity>
      <inertial>
        <pose>0.005462 0.061253 -0.08066 0 -0 0</pose>
        <mass>0.58842</mass>
        <inertia>
          <ixx>0.0101611</ixx>
          <ixy>5.35713e-05</ixy>
          <ixz>-2.26604e-05</ixz>
          <iyy>0.00881038</iyy>
          <iyz>0.00181935</iyz>
          <izz>0.00154978</izz>
        </inertia>
      </inertial>
      <visual name="LH_SHANK_fixed_joint_lump__LH_shank_fixed_visual">
        <pose>0 0 0 0 -0 1.5708</pose>
        <geometry>
          <mesh>
            <scale>1 1 1</scale>
            <uri>meshes/shank_r.dae</uri>
          </mesh>
        </geometry>
      </visual>
      <visual name="LH_SHANK_fixed_joint_lump__LH_FOOT_visual_1">
        <pose>0.01305 0.08795 -0.33797 0 -0 2.35619</pose>
        <geometry>
          <mesh>
            <scale>1 1 1</scale>
            <uri>meshes/foot.dae</uri>
          </mesh>
        </geometry>
      </visual>
    </link>
    <joint name="LH_KFE" type="revolute">
      <child>LH_SHANK</child>
      <parent>LH_THIGH</parent>
      <axis>
        <xyz>1 0 0</xyz>
        <limit>
          <lower>-9.42478</lower>
          <upper>9.42478</upper>
          <effort>80</effort>
          <velocity>7.5</velocity>
        </limit>
        <dynamics>
          <damping>0</damping>
          <friction>0</friction>
          <spring_reference>0</spring_reference>
          <spring_stiffness>0</spring_stiffness>
        </dynamics>
        <use_parent_model_frame>0</use_parent_model_frame>
      </axis>
    </joint>
    <link name="RF_HIP">
      <pose>0.2999 -0.104 0 -2.61799 0 0</pose>
      <gravity>false</gravity>
      <inertial>
        <pose>0.056763 0.015294 -0.008298 0 -0 0</pose>
        <mass>2.781</mass>
        <inertia>
          <ixx>0.00329553</ixx>
          <ixy>-1.10053e-05</ixy>
          <ixz>-0.000109121</ixz>
          <iyy>0.00504617</iyy>
          <iyz>0.000319492</iyz>
          <izz>0.00572872</izz>
        </inertia>
      </inertial>
      <visual name="RF_HIP_fixed_joint_lump__RF_hip_fixed_visual">
        <pose>0 0 0 2.61799 -0 0</pose>
        <geometry>
          <mesh>
            <scale>1 1 1</scale>
            <uri>meshes/hip_r.dae</uri>
          </mesh>
        </geometry>
      </visual>
      <visual name="RF_HIP_fixed_joint_lump__RF_HFE_visual_1">
        <pose>0.0599 0.072582 -0.041905 3.14159 0.523599 1.5708</pose>
        <geometry>
          <mesh>
            <scale>1 1 1</scale>
            <uri>meshes/drive.dae</uri>
          </mesh>
        </geometry>
      </visual>
    </link>
    <joint name="RF_HAA" type="revolute">
      <child>RF_HIP</child>
      <parent>base</parent>
      <axis>
        <xyz>1 0 0</xyz>
        <limit>
          <lower>-0.49</lower>
          <upper>0.72</upper>
          <effort>80</effort>
          <velocity>7.5</velocity>
        </limit>
        <dynamics>
          <damping>0</damping>
          <friction>0</friction>
          <spring_reference>0</spring_reference>
          <spring_stiffness>0</spring_stiffness>
        </dynamics>
        <use_parent_model_frame>0</use_parent_model_frame>
      </axis>
    </joint>
    <link name="RF_THIGH">
      <pose>0.3598 -0.18781 0 0 0 -1.5708</pose>
      <gravity>false</gravity>
      <inertial>
        <pose>0.030815 4.6e-05 -0.245696 0 -0 0</pose>
        <mass>3.071</mass>
        <inertia>
          <ixx>0.0295638</ixx>
          <ixy>4.43959e-05</ixy>
          <ixz>0.00414243</ixz>
          <iyy>0.029904</iyy>
          <iyz>0.000114794</iyz>
          <izz>0.00486108</izz>
        </inertia>
      </inertial>
      <visual name="RF_THIGH_fixed_joint_lump__RF_thigh_fixed_visual">
        <pose>0 0 0 0 0 -1.5708</pose>
        <geometry>
          <mesh>
            <scale>1 1 1</scale>
            <uri>meshes/thigh.dae</uri>
          </mesh>
        </geometry>
      </visual>
      <visual name="RF_THIGH_fixed_joint_lump__RF_KFE_visual_1">
        <pose>0.1003 -0 -0.285 0 -0 0</pose>
        <geometry>
          <mesh>
            <scale>1 1 1</scale>
            <uri>meshes/drive.dae</uri>
          </mesh>
        </geometry>
      </visual>
    </link>
    <joint name="RF_HFE" type="revolute">
      <child>RF_THIGH</child>
      <parent>RF_HIP</parent>
      <axis>
        <xyz>-1 0 0</xyz>
        <limit>
          <lower>-9.42478</lower>
          <upper>9.42478</upper>
          <effort>80</effort>
          <velocity>7.5</velocity>
        </limit>
        <dynamics>
          <damping>0</damping>
          <friction>0</friction>
          <spring_reference>0</spring_reference>
          <spring_stiffness>0</spring_stiffness>
        </dynamics>
        <use_parent_model_frame>0</use_parent_model_frame>
      </axis>
    </joint>
    <link name="RF_SHANK">
      <pose>0.3598 -0.28811 -0.285 0 0 -1.5708</pose>
      <gravity>false</gravity>
      <inertial>
        <pose>0.005462 0.061253 -0.08066 0 -0 0</pose>
        <mass>0.58842</mass>
        <inertia>
          <ixx>0.0101611</ixx>
          <ixy>5.35713e-05</ixy>
          <ixz>-2.26604e-05</ixz>
          <iyy>0.00881038</iyy>
          <iyz>0.00181935</iyz>
          <izz>0.00154978</izz>
        </inertia>
      </inertial>
      <visual name="RF_SHANK_fixed_joint_lump__RF_shank_fixed_visual">
        <pose>0 0 0 0 -0 1.5708</pose>
        <geometry>
          <mesh>
            <scale>1 1 1</scale>
            <uri>meshes/shank_r.dae</uri>
          </mesh>
        </geometry>
      </visual>
      <visual name="RF_SHANK_fixed_joint_lump__RF_FOOT_visual_1">
        <pose>0.01305 0.08795 -0.33797 0 -0 2.35619</pose>
        <geometry>
          <mesh>
            <scale>1 1 1</scale>
            <uri>meshes/foot.dae</uri>
          </mesh>
        </geometry>
      </visual>
    </link>
    <joint name="RF_KFE" type="revolute">
      <child>RF_SHANK</child>
      <parent>RF_THIGH</parent>
      <axis>
        <xyz>-1 0 0</xyz>
        <limit>
          <lower>-9.42478</lower>
          <upper>9.42478</upper>
          <effort>80</effort>
          <velocity>7.5</velocity>
        </limit>
        <dynamics>
          <damping>0</damping>
          <friction>0</friction>
          <spring_reference>0</spring_reference>
          <spring_stiffness>0</spring_stiffness>
        </dynamics>
        <use_parent_model_frame>0</use_parent_model_frame>
      </axis>
    </joint>
    <link name="RH_HIP">
      <pose>-0.2999 -0.104 0 2.61799 0 3.14159</pose>
      <gravity>false</gravity>
      <inertial>
        <pose>0.056661 -0.015294 -0.008298 0 -0 0</pose>
        <mass>2.781</mass>
        <inertia>
          <ixx>0.00329553</ixx>
          <ixy>-1.03882e-05</ixy>
          <ixz>0.000107062</ixz>
          <iyy>0.00504435</iyy>
          <iyz>-0.000319492</iyz>
          <izz>0.0057269</izz>
        </inertia>
      </inertial>
      <visual name="RH_HIP_fixed_joint_lump__RH_hip_fixed_visual">
        <pose>0 0 0 -2.61799 -0 -0</pose>
        <geometry>
          <mesh>
            <scale>1 1 1</scale>
            <uri>meshes/hip_l.dae</uri>
          </mesh>
        </geometry>
      </visual>
      <visual name="RH_HIP_fixed_joint_lump__RH_HFE_visual_1">
        <pose>0.0599 -0.072582 -0.041905 3.14159 0.523599 -1.5708</pose>
        <geometry>
          <mesh>
            <scale>1 1 1</scale>
            <uri>meshes/drive.dae</uri>
          </mesh>
        </geometry>
      </visual>
    </link>
    <joint name="RH_HAA" type="revolute">
      <child>RH_HIP</child>
      <parent>base</parent>
      <axis>
        <xyz>-1 0 0</xyz>
        <limit>
          <lower>-0.49</lower>
          <upper>0.72</upper>
          <effort>80</effort>
          <velocity>7.5</velocity>
        </limit>
        <dynamics>
          <damping>0</damping>
          <friction>0</friction>
          <spring_reference>0</spring_reference>
          <spring_stiffness>0</spring_stiffness>
        </dynamics>
        <use_parent_model_frame>0</use_parent_model_frame>
      </axis>
    </joint>
    <link name="RH_THIGH">
      <pose>-0.3598 -0.18781 -0 0 -0 -1.5708</pose>
      <gravity>false</gravity>
      <inertial>
        <pose>0.030815 4.6e-05 -0.245696 0 -0 0</pose>
        <mass>3.071</mass>
        <inertia>
          <ixx>0.0295638</ixx>
          <ixy>4.42919e-05</ixy>
          <ixz>0.00414243</ixz>
          <iyy>0.029904</iyy>
          <iyz>9.448e-05</iyz>
          <izz>0.00486108</izz>
        </inertia>
      </inertial>
      <visual name="RH_THIGH_fixed_joint_lump__RH_thigh_fixed_visual">
        <pose>0 0 0 0 0 -1.5708</pose>
        <geometry>
          <mesh>
            <scale>1 1 1</scale>
            <uri>meshes/thigh.dae</uri>
          </mesh>
        </geometry>
      </visual>
      <visual name="RH_THIGH_fixed_joint_lump__RH_KFE_visual_1">
        <pose>0.1003 -0 -0.285 0 -0 0</pose>
        <geometry>
          <mesh>
            <scale>1 1 1</scale>
            <uri>meshes/drive.dae</uri>
          </mesh>
        </geometry>
      </visual>
    </link>
    <joint name="RH_HFE" type="revolute">
      <child>RH_THIGH</child>
      <parent>RH_HIP</parent>
      <axis>
        <xyz>-1 0 0</xyz>
        <limit>
          <lower>-9.42478</lower>
          <upper>9.42478</upper>
          <effort>80</effort>
          <velocity>7.5</velocity>
        </limit>
        <dynamics>
          <damping>0</damping>
          <friction>0</friction>
          <spring_reference>0</spring_reference>
          <spring_stiffness>0</spring_stiffness>
        </dynamics>
        <use_parent_model_frame>0</use_parent_model_frame>
      </axis>
    </joint>
    <link name="RH_SHANK">
      <pose>-0.3598 -0.28811 -0.285 0 -0 -1.5708</pose>
      <gravity>false</gravity>
      <inertial>
        <pose>0.005462 -0.061253 -0.08066 0 -0 0</pose>
        <mass>0.58842</mass>
        <inertia>
          <ixx>0.0101611</ixx>
          <ixy>-5.35713e-05</ixy>
          <ixz>-2.26604e-05</ixz>
          <iyy>0.00881038</iyy>
          <iyz>-0.00181935</iyz>
          <izz>0.00154978</izz>
        </inertia>
      </inertial>
      <visual name="RH_SHANK_fixed_joint_lump__RH_shank_fixed_visual">
        <pose>0 0 0 0 0 -1.5708</pose>
        <geometry>
          <mesh>
            <scale>1 1 1</scale>
            <uri>meshes/shank_l.dae</uri>
          </mesh>
        </geometry>
      </visual>
      <visual name="RH_SHANK_fixed_joint_lump__RH_FOOT_visual_1">
        <pose>0.01305 -0.08795 -0.33797 0 0 -2.35619</pose>
        <geometry>
          <mesh>
            <scale>1 1 1</scale>
            <uri>meshes/foot.dae</uri>
          </mesh>
        </geometry>
      </visual>
    </link>
    <joint name="RH_KFE" type="revolute">
      <child>RH_SHANK</child>
      <parent>RH_THIGH</parent>
      <axis>
        <xyz>-1 0 0</xyz>
        <limit>
          <lower>-9.42478</lower>
          <upper>9.42478</upper>
          <effort>80</effort>
          <velocity>7.5</velocity>
        </limit>
        <dynamics>
          <damping>0</damping>
          <friction>0</friction>
          <spring_reference>0</spring_reference>
          <spring_stiffness>0</spring_stiffness>
        </dynamics>
        <use_parent_model_frame>0</use_parent_model_frame>
      </axis>
    </joint>
    <plugin filename="gz-sim-velocity-control-system" name="gz::sim::systems::VelocityControl">
      <topic>/cmd_vel</topic>
    </plugin>
    <!-- robot_base_frame=base_link is a TF child-frame LABEL only (no link named
         base_link exists; the actual link is 'base'). It is kept as base_link on
         purpose to preserve the tugbot DiffDrive odom->base_link output contract
         for the nav stack; a launch-provided static TF
         base_link -> anymal_c/base/scan_omni bridges the scan frame. Do not
         "fix" it to base. -->
    <plugin filename="gz-sim-odometry-publisher-system" name="gz::sim::systems::OdometryPublisher">
      <odom_frame>odom</odom_frame>
      <robot_base_frame>base_link</robot_base_frame>
      <odom_topic>/odom</odom_topic>
      <tf_topic>/tf</tf_topic>
      <odom_publish_frequency>30</odom_publish_frequency>
      <!-- Cancel the maze-world spawn (-11.011, -9.025) so /odom starts at
           zero like tugbot's wheel-integrated DiffDrive odom did: gz
           OdometryPublisher is world-anchored, and the online_slam entrance
           anchor + ICP prior assume a spawn-zeroed odom frame. -->
      <xyz_offset>11.011 9.025 0</xyz_offset>
      <dimensions>2</dimensions>
    </plugin>
    <plugin filename="gz-sim-joint-position-controller-system" name="gz::sim::systems::JointPositionController">
      <joint_name>LF_HAA</joint_name>
      <use_velocity_commands>true</use_velocity_commands>
      <initial_position>0.0</initial_position>
    </plugin>
    <plugin filename="gz-sim-joint-position-controller-system" name="gz::sim::systems::JointPositionController">
      <joint_name>LF_HFE</joint_name>
      <use_velocity_commands>true</use_velocity_commands>
      <initial_position>0.4</initial_position>
    </plugin>
    <plugin filename="gz-sim-joint-position-controller-system" name="gz::sim::systems::JointPositionController">
      <joint_name>LF_KFE</joint_name>
      <use_velocity_commands>true</use_velocity_commands>
      <initial_position>-0.8</initial_position>
    </plugin>
    <plugin filename="gz-sim-joint-position-controller-system" name="gz::sim::systems::JointPositionController">
      <joint_name>RF_HAA</joint_name>
      <use_velocity_commands>true</use_velocity_commands>
      <initial_position>0.0</initial_position>
    </plugin>
    <plugin filename="gz-sim-joint-position-controller-system" name="gz::sim::systems::JointPositionController">
      <joint_name>RF_HFE</joint_name>
      <use_velocity_commands>true</use_velocity_commands>
      <initial_position>0.4</initial_position>
    </plugin>
    <plugin filename="gz-sim-joint-position-controller-system" name="gz::sim::systems::JointPositionController">
      <joint_name>RF_KFE</joint_name>
      <use_velocity_commands>true</use_velocity_commands>
      <initial_position>-0.8</initial_position>
    </plugin>
    <plugin filename="gz-sim-joint-position-controller-system" name="gz::sim::systems::JointPositionController">
      <joint_name>LH_HAA</joint_name>
      <use_velocity_commands>true</use_velocity_commands>
      <initial_position>0.0</initial_position>
    </plugin>
    <plugin filename="gz-sim-joint-position-controller-system" name="gz::sim::systems::JointPositionController">
      <joint_name>LH_HFE</joint_name>
      <use_velocity_commands>true</use_velocity_commands>
      <initial_position>-0.4</initial_position>
    </plugin>
    <plugin filename="gz-sim-joint-position-controller-system" name="gz::sim::systems::JointPositionController">
      <joint_name>LH_KFE</joint_name>
      <use_velocity_commands>true</use_velocity_commands>
      <initial_position>0.8</initial_position>
    </plugin>
    <plugin filename="gz-sim-joint-position-controller-system" name="gz::sim::systems::JointPositionController">
      <joint_name>RH_HAA</joint_name>
      <use_velocity_commands>true</use_velocity_commands>
      <initial_position>0.0</initial_position>
    </plugin>
    <plugin filename="gz-sim-joint-position-controller-system" name="gz::sim::systems::JointPositionController">
      <joint_name>RH_HFE</joint_name>
      <use_velocity_commands>true</use_velocity_commands>
      <initial_position>-0.4</initial_position>
    </plugin>
    <plugin filename="gz-sim-joint-position-controller-system" name="gz::sim::systems::JointPositionController">
      <joint_name>RH_KFE</joint_name>
      <use_velocity_commands>true</use_velocity_commands>
      <initial_position>0.8</initial_position>
    </plugin>
  </model>
</sdf>
