<?xml version="1.0"?>
<sdf version="1.8">
  <model name="mr_buggy3">
    <static>false</static>
    <self_collide>false</self_collide>
    <!-- PHYSICAL chassis (ackermann-physics phase): gravity on, real wheel contact,
         gz AckermannSteering (Harmonic naming; the upstream SDF's duplicate
         right_joint bug is FIXED here: front_right + rear_right). Geometry, masses,
         friction ported field-for-field from tmp_resources/MR-Buggy3; links/joints
         renamed dash-free; sensors/odometry kept from the kinematic phase (frames
         unchanged: mr_buggy3/base/lidar_3d, mr_buggy3/base/camera_front).
         Min turn radius = wheel_base/tan(steering_limit) ~= 0.41 m: the motion layer
         compensates with N-point turns (ackermann_maneuvers). -->
    <link name="base">
      <inertial>
        <mass>3.0</mass>
        <inertia>
          <ixx>0.0054</ixx><ixy>0</ixy><ixz>0</ixz>
          <iyy>0.0252</iyy><iyz>0</iyz><izz>0.0252</izz>
        </inertia>
      </inertial>
      <visual name="base_visual">
        <pose>.1371 0 -.0115 -0.018 0 1.5707</pose>
        <geometry><mesh><uri>model://mr_buggy3/meshes/BaseReduced.dae</uri></mesh></geometry>
      </visual>
      <visual name="top_visual">
        <pose>.1371 0 -.0115 -0.018 0 1.5707</pose>
        <geometry><mesh><uri>model://mr_buggy3/meshes/TopReduced.dae</uri></mesh></geometry>
      </visual>
      <collision name="base_collision">
        <pose>0 0 .06 0 0 0</pose>
        <geometry><box><size>.3 .09 .12</size></box></geometry>
      </collision>
      <sensor name="lidar_3d" type="gpu_lidar">
        <!-- Centered: SCAN_OFFSET_X=0 contract; identical to the kinematic phase. -->
        <pose>0 0 0.30 0 0 0</pose>
        <topic>/lidar/points</topic>
        <always_on>1</always_on>
        <visualize>false</visualize>
        <update_rate>10</update_rate>
        <lidar>
          <scan>
            <horizontal>
              <samples>1800</samples>
              <resolution>1.0</resolution>
              <min_angle>-3.14159</min_angle>
              <max_angle>3.14159</max_angle>
            </horizontal>
            <vertical>
              <samples>16</samples>
              <resolution>1</resolution>
              <min_angle>-0.261799</min_angle>
              <max_angle>0.261799</max_angle>
            </vertical>
          </scan>
          <range>
            <min>0.05</min>
            <max>100</max>
            <resolution>0.01</resolution>
          </range>
          <noise>
            <type>gaussian</type>
            <mean>0</mean>
            <stddev>0.01</stddev>
          </noise>
        </lidar>
      </sensor>
      <sensor name="camera_front" type="camera">
        <always_on>1</always_on>
        <update_rate>20</update_rate>
        <pose>0.12 0 0.15 0 0 0</pose>
        <topic>/camera/front/image</topic>
        <camera name="camera_front">
          <horizontal_fov>2.19911</horizontal_fov>
          <camera_info_topic>/camera/front/camera_info</camera_info_topic>
          <lens>
            <intrinsics>
              <fx>183.43</fx>
              <fy>183.43</fy>
              <cx>360.5</cx>
              <cy>270.5</cy>
              <s>0</s>
            </intrinsics>
          </lens>
          <image>
            <width>720</width>
            <height>540</height>
          </image>
          <clip>
            <near>0.02</near>
            <far>100</far>
          </clip>
          <noise>
            <type>gaussian</type>
            <mean>0</mean>
            <stddev>0.007</stddev>
          </noise>
        </camera>
      </sensor>
    </link>
    <link name="front_right_steering">
      <pose relative_to="front_right_steering_joint">0 0 0 0 0 0</pose>
      <inertial>
        <mass>0.005</mass>
        <inertia><ixx>0.0000018</ixx><iyy>0.0000018</iyy><izz>0.0000018</izz></inertia>
      </inertial>
    </link>
    <link name="front_left_steering">
      <pose relative_to="front_left_steering_joint">0 0 0 0 0 0</pose>
      <inertial>
        <mass>0.005</mass>
        <inertia><ixx>0.0000018</ixx><iyy>0.0000018</iyy><izz>0.0000018</izz></inertia>
      </inertial>
    </link>
    <link name="front_right_wheel">
      <pose relative_to="front_right_wheel_joint">0 0 0 0 0 0</pose>
      <inertial>
        <mass>.05</mass>
        <inertia><ixx>0.00003331</ixx><iyy>0.0000204</iyy><izz>0.0000204</izz></inertia>
      </inertial>
      <visual name="front_right_wheel_visual">
        <pose>0 0 0 0 0 0</pose>
        <geometry><mesh><uri>model://mr_buggy3/meshes/Wheel.dae</uri></mesh></geometry>
      </visual>
      <collision name="front_right_wheel_collision">
        <pose>0 .015 0 -1.5707 0 0</pose>
        <geometry><cylinder><length>0.03</length><radius>0.0365</radius></cylinder></geometry>
        <surface>
          <friction>
            <ode><mu>0.5</mu><mu2>1.0</mu2><fdir1>0 0 1</fdir1></ode>
          </friction>
        </surface>
      </collision>
    </link>
    <link name="front_left_wheel">
      <pose relative_to="front_left_wheel_joint">0 0 0 0 0 0</pose>
      <inertial>
        <mass>.05</mass>
        <inertia><ixx>0.00003331</ixx><iyy>0.0000204</iyy><izz>0.0000204</izz></inertia>
      </inertial>
      <visual name="front_left_wheel_visual">
        <pose>0 0 0 0 0 3.14159</pose>
        <geometry><mesh><uri>model://mr_buggy3/meshes/Wheel.dae</uri></mesh></geometry>
      </visual>
      <collision name="front_left_wheel_collision">
        <pose>0 -.015 0 -1.5707 0 0</pose>
        <geometry><cylinder><length>0.03</length><radius>0.0365</radius></cylinder></geometry>
        <surface>
          <friction>
            <ode><mu>0.5</mu><mu2>1.0</mu2><fdir1>0 0 1</fdir1></ode>
          </friction>
        </surface>
      </collision>
    </link>
    <link name="rear_right_wheel">
      <pose relative_to="rear_right_wheel_joint">0 0 0 0 0 0</pose>
      <inertial>
        <mass>.05</mass>
        <inertia><ixx>0.00003331</ixx><iyy>0.0000204</iyy><izz>0.0000204</izz></inertia>
      </inertial>
      <visual name="rear_right_wheel_visual">
        <pose>0 0 0 0 0 0</pose>
        <geometry><mesh><uri>model://mr_buggy3/meshes/Wheel.dae</uri></mesh></geometry>
      </visual>
      <collision name="rear_right_wheel_collision">
        <pose>0 .015 0 -1.5707 0 0</pose>
        <geometry><cylinder><length>0.03</length><radius>0.0365</radius></cylinder></geometry>
        <surface>
          <friction>
            <ode><mu>0.5</mu><mu2>1.0</mu2><fdir1>0 0 1</fdir1></ode>
          </friction>
        </surface>
      </collision>
    </link>
    <link name="rear_left_wheel">
      <pose relative_to="rear_left_wheel_joint">0 0 0 0 0 0</pose>
      <inertial>
        <mass>.05</mass>
        <inertia><ixx>0.00003331</ixx><iyy>0.0000204</iyy><izz>0.0000204</izz></inertia>
      </inertial>
      <visual name="rear_left_wheel_visual">
        <pose>0 0 0 0 0 3.14159</pose>
        <geometry><mesh><uri>model://mr_buggy3/meshes/Wheel.dae</uri></mesh></geometry>
      </visual>
      <collision name="rear_left_wheel_collision">
        <pose>0 -.015 0 -1.5707 0 0</pose>
        <geometry><cylinder><length>0.03</length><radius>0.0365</radius></cylinder></geometry>
        <surface>
          <friction>
            <ode><mu>0.5</mu><mu2>1.0</mu2><fdir1>0 0 1</fdir1></ode>
          </friction>
        </surface>
      </collision>
    </link>
    <joint name="front_right_steering_joint" type="revolute">
      <parent>base</parent>
      <child>front_right_steering</child>
      <pose relative_to="base">.112 -.10 0 0 0 0</pose>
      <axis>
        <xyz>0 0 1</xyz>
        <limit>
          <lower>-0.6</lower>
          <upper>0.6</upper>
          <velocity>1.0</velocity>
          <effort>25</effort>
        </limit>
      </axis>
    </joint>
    <joint name="front_left_steering_joint" type="revolute">
      <parent>base</parent>
      <child>front_left_steering</child>
      <pose relative_to="base">.112 .10 0 0 0 0</pose>
      <axis>
        <xyz>0 0 1</xyz>
        <limit>
          <lower>-0.6</lower>
          <upper>0.6</upper>
          <velocity>1.0</velocity>
          <effort>25</effort>
        </limit>
      </axis>
    </joint>
    <joint name="front_right_wheel_joint" type="revolute">
      <parent>front_right_steering</parent>
      <child>front_right_wheel</child>
      <pose relative_to="front_right_steering_joint">0 0 0 0 0 0</pose>
      <axis>
        <xyz>0 1 0</xyz>
        <limit>
          <lower>-1.79769e+308</lower>
          <upper>1.79769e+308</upper>
        </limit>
      </axis>
    </joint>
    <joint name="front_left_wheel_joint" type="revolute">
      <parent>front_left_steering</parent>
      <child>front_left_wheel</child>
      <pose relative_to="front_left_steering_joint">0 0 0 0 0 0</pose>
      <axis>
        <xyz>0 1 0</xyz>
        <limit>
          <lower>-1.79769e+308</lower>
          <upper>1.79769e+308</upper>
        </limit>
      </axis>
    </joint>
    <joint name="rear_right_wheel_joint" type="revolute">
      <parent>base</parent>
      <child>rear_right_wheel</child>
      <pose relative_to="base">-.1135 -.10 0 0 0 0</pose>
      <axis>
        <xyz>0 1 0</xyz>
        <limit>
          <lower>-1.79769e+308</lower>
          <upper>1.79769e+308</upper>
        </limit>
      </axis>
    </joint>
    <joint name="rear_left_wheel_joint" type="revolute">
      <parent>base</parent>
      <child>rear_left_wheel</child>
      <pose relative_to="base">-.1135 .10 0 0 0 0</pose>
      <axis>
        <xyz>0 1 0</xyz>
        <limit>
          <lower>-1.79769e+308</lower>
          <upper>1.79769e+308</upper>
        </limit>
      </axis>
    </joint>
    <plugin filename="gz-sim-ackermann-steering-system" name="gz::sim::systems::AckermannSteering">
      <left_joint>front_left_wheel_joint</left_joint>
      <left_joint>rear_left_wheel_joint</left_joint>
      <right_joint>front_right_wheel_joint</right_joint>
      <right_joint>rear_right_wheel_joint</right_joint>
      <left_steering_joint>front_left_steering_joint</left_steering_joint>
      <right_steering_joint>front_right_steering_joint</right_steering_joint>
      <kingpin_width>.18</kingpin_width>
      <steering_limit>0.5</steering_limit>
      <wheel_base>.2255</wheel_base>
      <wheel_separation>.2</wheel_separation>
      <wheel_radius>0.0365</wheel_radius>
      <min_velocity>-100</min_velocity>
      <max_velocity>100</max_velocity>
      <min_acceleration>-5</min_acceleration>
      <max_acceleration>5</max_acceleration>
      <topic>/cmd_vel</topic>
    </plugin>
    <plugin filename="gz-sim-odometry-publisher-system" name="gz::sim::systems::OdometryPublisher">
      <odom_frame>odom</odom_frame>
      <robot_base_frame>base_link</robot_base_frame>
      <odom_topic>/odom</odom_topic>
      <tf_topic>/tf</tf_topic>
      <odom_publish_frequency>30</odom_publish_frequency>
      <dimensions>3</dimensions>
    </plugin>
  </model>
</sdf>
