<?xml version='1.0' encoding='ASCII'?>
<sdf version="1.7">
  <model name="tugbot">
    <self_collide>false</self_collide>
    <static>false</static>
    <link name="base_link">
      <pose>0 0 0 0 0 0</pose>
      <inertial>
        <pose>-0.1 0 0.1 0 0 0</pose>
        <mass>46.2</mass>
        <inertia>
          <ixx>1.55925</ixx>
          <ixy>0</ixy>
          <ixz>0</ixz>
          <iyy>1.55925</iyy>
          <iyz>0</iyz>
          <izz>1.55925</izz>
        </inertia>
      </inertial>
      <collision name="base_link_collision">
        <pose>0 0 0 0 0 0</pose>
        <geometry>
          <mesh>
            <uri>meshes/base/tugbot_simp.stl</uri>
          </mesh>
        </geometry>
      </collision>
      <visual name="base_link_visual">
        <pose>0 0 0 0 0 0</pose>
        <geometry>
          <mesh>
            <uri>meshes/base/tugbot_simp.dae</uri>
          </mesh>
        </geometry>
      </visual>
      <visual name="movai_logo_visual">
        <pose>0 0 0 0 0 0</pose>
        <geometry>
          <mesh>
            <uri>meshes/base/movai_logo.dae</uri>
          </mesh>
        </geometry>
        <material>
          <diffuse>1.0 1.0 1.0</diffuse>
          <pbr>
            <metal>
              <albedo_map>meshes/base/movai-logo.png</albedo_map>
            </metal>
          </pbr>
        </material>
      </visual>
      <visual name="light_link_visual">
        <pose>-0.1 0 0.1945 0 1.57079632679 0</pose>
        <geometry>
          <mesh>
            <scale>1.0 1.0 1.0</scale>
            <uri>meshes/light_link/light_led.stl</uri>
          </mesh>
        </geometry>
        <material>
          <ambient>0.0 0.0 0 1</ambient>
          <diffuse>0.0 0.0 0 1</diffuse>
          <specular>0 0 0 1</specular>
          <emissive>0 1 0 1</emissive>
        </material>
      </visual>
      <visual name="warnign_light_visual">
        <pose>-0.099 0 0.195 0 1.57079632679 0</pose>
        <geometry>
          <mesh>
            <scale>1.02 1.02 1.02</scale>
            <uri>meshes/light_link/light.stl</uri>
          </mesh>
        </geometry>
        <material>
          <ambient>0.1 0.05 0 0.5</ambient>
          <diffuse>1 0.5 0 0.5</diffuse>
          <specular>1 0.5 0 0.5</specular>
          <emissive>1 0.5 0 0.5</emissive>
        </material>
      </visual>
    </link>
    <link name="imu_link">
      <pose>0.14 0.02 0.25 0 0 -1.57</pose>
      <sensor name="imu" type="imu">
        <update_rate>30</update_rate>
        <visualize>false</visualize>
      </sensor>
    </link>
    <joint name="imu_link_joint" type="fixed">
      <child>imu_link</child>
      <parent>base_link</parent>
    </joint>
    <link name="warnign_light">
      <pose>-0.185 0 0.46 0 0 0</pose>
      <inertial>
        <pose>0 0 0 0 0 0</pose>
        <mass>0.1</mass>
        <inertia>
          <ixx>0.000016875</ixx>
          <ixy>0</ixy>
          <ixz>0</ixz>
          <iyy>0.00000001</iyy>
          <iyz>0</iyz>
          <izz>0.000016875</izz>
        </inertia>
      </inertial>
      <light name="warnign_light_lamp" type="spot">
        <pose>-0.04 0 0 0 1.57079632679 0</pose>
        <attenuation>
          <range>5</range>
          <linear>0</linear>
          <constant>0.1</constant>
          <quadratic>0.0025</quadratic>
        </attenuation>
        <diffuse>1 0.5 0 1</diffuse>
        <specular>1 0.5 0 1</specular>
        <spot>
          <inner_angle>0.9</inner_angle>
          <outer_angle>1.0</outer_angle>
          <falloff>2.0</falloff>
        </spot>
        <direction>0 0 -1</direction>
        <cast_shadows>1</cast_shadows>
      </light>
    </link>
    <joint name="warnign_light_joint" type="revolute">
      <child>warnign_light</child>
      <parent>base_link</parent>
      <axis>
        <xyz>0 0 1</xyz>
        <limit>
          <effort>1000</effort>
          <velocity>20.0</velocity>
        </limit>
      </axis>
    </joint>
    <link name="camera_link">
      <pose relative_to="base_link">0.30 0 0.55 0 0 0</pose>
      <sensor name="color" type="camera">
        <pose>0 0 0 0 0 0</pose>
        <update_rate>15</update_rate>
        <always_on>1</always_on>
        <visualize>true</visualize>
        <topic>/camera/image_raw</topic>
        <camera>
          <horizontal_fov>1.047</horizontal_fov>
          <image>
            <width>640</width>
            <height>480</height>
            <format>R8G8B8</format>
          </image>
          <clip>
            <near>0.05</near>
            <far>20.0</far>
          </clip>
          <optical_frame_id>camera_optical_frame</optical_frame_id>
        </camera>
      </sensor>
    </link>
    <joint name="camera_link_joint" type="fixed">
      <parent>base_link</parent>
      <child>camera_link</child>
    </joint>
    <link name="scan_front">
      <pose>0.221 0 0.1404 0 0 0</pose>
      <sensor name="scan_front" type="gpu_lidar">
        <update_rate>10</update_rate>
        <lidar>
          <scan>
            <horizontal>
              <samples>674</samples>
              <resolution>1</resolution>
              <min_angle>-1.47043991089</min_angle>
              <max_angle>1.47043991089</max_angle>
            </horizontal>
          </scan>
          <range>
            <min>0.01</min>
            <max>5.0</max>
            <resolution>0.01</resolution>
          </range>
        </lidar>
      </sensor>
    </link>
    <joint name="scan_front_joint" type="fixed">
      <child>scan_front</child>
      <parent>base_link</parent>
    </joint>
    <link name="scan_back">
      <pose>-0.2075 0 0.205 0 0 3.141592654</pose>
      <sensor name="scan_back" type="gpu_lidar">
        <update_rate>5</update_rate>
        <lidar>
          <scan>
            <horizontal>
              <samples>480</samples>
              <resolution>1</resolution>
              <min_angle>-1.47043991089</min_angle>
              <max_angle>1.47043991089</max_angle>
            </horizontal>
          </scan>
          <range>
            <min>0.01</min>
            <max>5.0</max>
            <resolution>0.01</resolution>
          </range>
        </lidar>
      </sensor>
    </link>
    <joint name="scan_back_joint" type="fixed">
      <child>scan_back</child>
      <parent>base_link</parent>
    </joint>
    <link name="scan_omni">
      <pose>-0.1855 0 0.5318 0 0 0</pose>
      <visual name="velodyne_base">
        <pose>0 0 -0.035 0 0 0</pose>
        <geometry>
          <cylinder>
            <radius>0.06</radius>
            <length>0.0015</length>
          </cylinder>
        </geometry>
      </visual>
      <visual name="velodyne_suport_1">
        <pose>-0.035 0.035 -0.08 0 0 0</pose>
        <geometry>
          <cylinder>
            <radius>0.005</radius>
            <length>0.09</length>
          </cylinder>
        </geometry>
      </visual>
      <visual name="velodyne_suport_2">
        <pose>-0.035 -0.035 -0.08 0 0 0</pose>
        <geometry>
          <cylinder>
            <radius>0.005</radius>
            <length>0.09</length>
          </cylinder>
        </geometry>
      </visual>
      <visual name="velodyne_suport_3">
        <pose>0.0495 0 -0.08 0 0 0</pose>
        <geometry>
          <cylinder>
            <radius>0.005</radius>
            <length>0.09</length>
          </cylinder>
        </geometry>
      </visual>
      <visual name="velodyne_base_link_visual_base">
        <pose>0 0 -0.035 0 0 0</pose>
        <geometry>
          <mesh>
            <scale>1 1 1</scale>
            <uri>meshes/VLP16_base_1.dae</uri>
          </mesh>
        </geometry>
      </visual>
      <visual name="velodyne_base_link_visual_sensor">
        <pose>0 0 -0.035 0 0 0</pose>
        <geometry>
          <mesh>
            <scale>1 1 1</scale>
            <uri>meshes/VLP16_base_2.dae</uri>
          </mesh>
        </geometry>
      </visual>
      <visual name="base_link_velodyne_visual_scan">
        <pose>0 0 -0.035 0 0 0</pose>
        <geometry>
          <mesh>
            <scale>1 1 1</scale>
            <uri>meshes/VLP16_scan.dae</uri>
          </mesh>
        </geometry>
      </visual>
      <sensor name="scan_omni" type="gpu_lidar">
        <topic>/scan</topic>
        <always_on>1</always_on>
        <visualize>true</visualize>
        <update_rate>10</update_rate>
        <lidar>
          <scan>
            <horizontal>
              <samples>900</samples>
              <resolution>1</resolution>
              <min_angle>-3.141592654</min_angle>
              <max_angle>3.141592654</max_angle>
            </horizontal>
          </scan>
          <range>
            <min>0.2</min>
            <max>100.0</max>
            <resolution>0.01</resolution>
          </range>
        </lidar>
      </sensor>
    </link>
    <joint name="scan_omni_joint" type="fixed">
      <child>scan_omni</child>
      <parent>base_link</parent>
    </joint>
    <link name="gripper">
      <pose>-0.35 0 0.1 0 0 0</pose>
      <inertial>
        <pose>0 0 0 0 -0 0</pose>
        <mass>1</mass>
        <inertia>
          <ixx>0.001666667</ixx>
          <ixy>0</ixy>
          <ixz>0</ixz>
          <iyy>0.001666667</iyy>
          <iyz>0</iyz>
          <izz>0.001666667</izz>
        </inertia>
      </inertial>
      <collision name="gripper_collision">
        <pose>-0.005 0 0 0 -0 0</pose>
        <max_contacts>5</max_contacts>
        <geometry>
          <box>
            <size>0.15 0.1 0.1</size>
          </box>
        </geometry>
        <surface>
          <contact>
            <ode>
              <kp>1000000.0</kp>
              <kd>1</kd>
              <min_depth>0.01</min_depth>
              <max_vel>1</max_vel>
            </ode>
          </contact>
          <friction>
            <ode>
              <mu>1.16</mu>
              <mu2>1.16</mu2>
            </ode>
          </friction>
        </surface>
      </collision>
      <visual name="gripper_visual">
        <pose>0 0 0 -1.57079632679 0 0</pose>
        <geometry>
          <mesh>
            <scale>1 1 1</scale>
            <uri>meshes/gripper2/gripper2.dae</uri>
          </mesh>
        </geometry>
      </visual>
      <sensor name="sensor_contact" type="gpu_lidar">
        <pose>-0.075 0 0.035 0 0 3.141592654</pose>
        <update_rate>10</update_rate>
        <lidar>
          <scan>
            <horizontal>
              <samples>3</samples>
              <resolution>1</resolution>
              <min_angle>-0.02</min_angle>
              <max_angle>0.02</max_angle>
            </horizontal>
          </scan>
          <range>
            <min>0.001</min>
            <max>0.01</max>
            <resolution>0.001</resolution>
          </range>
        </lidar>
      </sensor>
    </link>
    <joint name="gripper_joint" type="revolute">
      <pose>0.35 0 0.09 0 0 0</pose>
      <child>gripper</child>
      <parent>base_link</parent>
      <axis>
        <xyz>0 0 1</xyz>
        <limit>
          <lower>-0.7</lower>
          <upper>0.7</upper>
          <effort>4</effort>
          <velocity>0.5</velocity>
        </limit>
        <dynamics>
          <friction>0.5</friction>
        </dynamics>
      </axis>
    </joint>
    <link name="gripper_hand">
      <pose>-0.463 0 0.1 0 0 0</pose>
      <inertial>
        <pose>0 0 0 0 0 0</pose>
        <mass>0.2</mass>
        <inertia>
          <ixx>0.000016</ixx>
          <ixy>0</ixy>
          <ixz>0</ixz>
          <iyy>0.000016</iyy>
          <iyz>0</iyz>
          <izz>0.000016</izz>
        </inertia>
      </inertial>
      <collision name="gripper_hand_collision">
        <pose>0.015 0 0.006 0 0 0</pose>
        <geometry>
          <box>
            <size>0.04 0.1 0.017</size>
          </box>
        </geometry>
        <max_contacts>5</max_contacts>
        <surface>
          <contact>
            <ode>
              <kp>1000000.0</kp>
              <kd>1</kd>
              <min_depth>0.01</min_depth>
              <max_vel>1</max_vel>
            </ode>
          </contact>
          <friction>
            <ode>
              <mu>1.16</mu>
              <mu2>1.16</mu2>
            </ode>
          </friction>
        </surface>
      </collision>
      <visual name="gripper_hand_visual">
        <pose>0 0 0 1.570796327 0 1.570796327</pose>
        <geometry>
          <mesh>
            <scale>0.001 0.001 0.001</scale>
            <uri>meshes/gripper2/gripper_hand.stl</uri>
          </mesh>
        </geometry>
        <material>
          <ambient>0.1 0.1 0.1 1</ambient>
          <diffuse>0.3 0.3 0.3 1</diffuse>
          <specular>1 1 1 1</specular>
          <emissive>0 0 0 1</emissive>
        </material>
      </visual>
      <collision name="gripper_hand_sideL_collision">
        <pose>0 0.08 0.03 0 0 0</pose>
        <geometry>
          <box>
            <size>0.01 0.05 0.07</size>
          </box>
        </geometry>
        <surface>
          <contact>
            <ode>
              <kp>1000000.0</kp>
              <kd>1</kd>
              <min_depth>0.01</min_depth>
              <max_vel>1</max_vel>
            </ode>
          </contact>
          <friction>
            <ode>
              <mu>1.16</mu>
              <mu2>1.16</mu2>
            </ode>
          </friction>
        </surface>
      </collision>
      <collision name="gripper_hand_sideL_slide_collision">
        <pose>0 0.055 0.03 0.9 0 0</pose>
        <geometry>
          <box>
            <size>0.01 0.055 0.04</size>
          </box>
        </geometry>
        <surface>
          <contact>
            <ode>
              <kp>1000000.0</kp>
              <kd>1</kd>
              <min_depth>0.01</min_depth>
              <max_vel>1</max_vel>
            </ode>
          </contact>
          <friction>
            <ode>
              <mu>0</mu>
              <mu2>0</mu2>
            </ode>
          </friction>
        </surface>
      </collision>
      <collision name="gripper_hand_sideR_collision">
        <pose>0 -0.08 0.03 0 0 0</pose>
        <geometry>
          <box>
            <size>0.01 0.05 0.07</size>
          </box>
        </geometry>
        <surface>
          <contact>
            <ode>
              <kp>1000000.0</kp>
              <kd>1</kd>
              <min_depth>0.01</min_depth>
              <max_vel>1</max_vel>
            </ode>
          </contact>
          <friction>
            <ode>
              <mu>1.16</mu>
              <mu2>1.16</mu2>
            </ode>
          </friction>
        </surface>
      </collision>
      <collision name="gripper_hand_sideR_slide_collision">
        <pose>0 -0.055 0.03 -0.9 0 0</pose>
        <geometry>
          <box>
            <size>0.01 0.055 0.04</size>
          </box>
        </geometry>
        <surface>
          <contact>
            <ode>
              <kp>1000000.0</kp>
              <kd>1</kd>
              <min_depth>0.01</min_depth>
              <max_vel>1</max_vel>
            </ode>
          </contact>
          <friction>
            <ode>
              <mu>0</mu>
              <mu2>0</mu2>
            </ode>
          </friction>
        </surface>
      </collision>
    </link>
    <joint name="gripper_hand_joint" type="revolute">
      <pose>0.2 0 0 0 0 0</pose>
      <child>gripper_hand</child>
      <parent>gripper</parent>
      <axis>
        <xyz>0 1 0</xyz>
        <limit>
          <lower>-0.35</lower>
          <upper>0.1</upper>
          <effort>100</effort>
          <velocity>0.5</velocity>
        </limit>
      </axis>
    </joint>
    <link name="wheel_front">
      <pose>0.145 0 0.0345 1.570796327 0 0</pose>
      <inertial>
        <pose>0 0 0 0 0 0</pose>
        <mass>0.1</mass>
        <inertia>
          <ixx>0.0000175</ixx>
          <ixy>0</ixy>
          <ixz>0</ixz>
          <iyy>0.0000175</iyy>
          <iyz>0</iyz>
          <izz>0.0000175</izz>
        </inertia>
      </inertial>
      <collision name="wheel_front_collision">
        <pose>0 0 0 0 0 0</pose>
        <geometry>
          <sphere>
            <radius>0.025</radius>
          </sphere>
        </geometry>
        <max_contacts>2</max_contacts>
        <surface>
          <contact>
            <ode>
              <kp>1000000.0</kp>
              <kd>1</kd>
              <min_depth>0.01</min_depth>
              <max_vel>1</max_vel>
            </ode>
          </contact>
          <friction>
            <ode>
              <mu>1.16</mu>
              <mu2>1.16</mu2>
            </ode>
          </friction>
        </surface>
      </collision>
    </link>
    <joint name="wheel_front_joint" type="ball">
      <child>wheel_front</child>
      <parent>base_link</parent>
      <axis>
        <limit>
          <effort>100</effort>
        </limit>
        <dynamics>
          <spring_reference>0</spring_reference>
          <spring_stiffness>0</spring_stiffness>
          <damping>10</damping>
        </dynamics>
      </axis>
    </joint>
    <link name="wheel_back">
      <pose>-0.225 0 0.035 1.570796327 0 0</pose>
      <inertial>
        <pose>0 0 0 0 0 0</pose>
        <mass>0.1</mass>
        <inertia>
          <ixx>0.0000175</ixx>
          <ixy>0</ixy>
          <ixz>0</ixz>
          <iyy>0.0000175</iyy>
          <iyz>0</iyz>
          <izz>0.0000175</izz>
        </inertia>
      </inertial>
      <collision name="wheel_back_collision">
        <pose>0 0 0 0 0 0</pose>
        <geometry>
          <sphere>
            <radius>0.035</radius>
          </sphere>
        </geometry>
        <max_contacts>2</max_contacts>
        <surface>
          <contact>
            <ode>
              <kp>1000000.0</kp>
              <kd>1</kd>
              <min_depth>0.01</min_depth>
              <max_vel>1</max_vel>
            </ode>
          </contact>
          <friction>
            <ode>
              <mu>1.16</mu>
              <mu2>1.16</mu2>
            </ode>
          </friction>
        </surface>
      </collision>
    </link>
    <joint name="wheel_back_joint" type="ball">
      <child>wheel_back</child>
      <parent>base_link</parent>
      <axis>
        <limit>
          <effort>100</effort>
        </limit>
        <dynamics>
          <spring_reference>0</spring_reference>
          <spring_stiffness>0</spring_stiffness>
          <damping>10</damping>
        </dynamics>
      </axis>
    </joint>
    <link name="wheel_left">
      <pose>0 0.257 0.195 -1.570796327 0 0</pose>
      <inertial>
        <pose>0 0 0 0 0 0</pose>
        <mass>0.1</mass>
        <inertia>
          <ixx>0.0000175</ixx>
          <ixy>0</ixy>
          <ixz>0</ixz>
          <iyy>0.0000175</iyy>
          <iyz>0</iyz>
          <izz>0.00003125</izz>
        </inertia>
      </inertial>
      <collision name="wheel_left_collision">
        <pose>0 0 0 0 0 0</pose>
        <geometry>
          <cylinder>
            <radius>0.195</radius>
            <length>0.05</length>
          </cylinder>
        </geometry>
        <max_contacts>5</max_contacts>
        <surface>
          <contact>
            <ode>
              <kp>1000000.0</kp>
              <kd>1</kd>
              <min_depth>0.01</min_depth>
              <max_vel>1</max_vel>
            </ode>
          </contact>
          <friction>
            <ode>
              <mu>1.16</mu>
              <mu2>10</mu2>
              <fdir1>1 0 0</fdir1>
            </ode>
          </friction>
        </surface>
      </collision>
      <visual name="wheel_left_visual">
        <pose>0 0 -0.03 0 0 0</pose>
        <geometry>
          <mesh>
            <scale>0.98 0.98 1.0</scale>
            <uri>meshes/wheel/wheel.dae</uri>
          </mesh>
        </geometry>
      </visual>
    </link>
    <joint name="wheel_left_joint" type="revolute">
      <child>wheel_left</child>
      <parent>base_link</parent>
      <axis>
        <xyz>0 0 1</xyz>
        <limit>
          <effort>9.6</effort>
        </limit>
        <dynamics>
          <damping>3.0</damping>
          <friction>0.5</friction>
        </dynamics>
      </axis>
    </joint>
    <link name="wheel_right">
      <pose>0 -0.257 0.195 1.570796327 0 0</pose>
      <inertial>
        <pose>0 0 0 0 0 0</pose>
        <mass>0.1</mass>
        <inertia>
          <ixx>0.0000175</ixx>
          <ixy>0</ixy>
          <ixz>0</ixz>
          <iyy>0.0000175</iyy>
          <iyz>0</iyz>
          <izz>0.00003125</izz>
        </inertia>
      </inertial>
      <collision name="wheel_right_collision">
        <pose>0 0 0 0 0 0</pose>
        <geometry>
          <cylinder>
            <radius>0.195</radius>
            <length>0.05</length>
          </cylinder>
        </geometry>
        <max_contacts>5</max_contacts>
        <surface>
          <contact>
            <ode>
              <kp>1000000.0</kp>
              <kd>1</kd>
              <min_depth>0.01</min_depth>
              <max_vel>1</max_vel>
            </ode>
          </contact>
          <friction>
            <ode>
              <mu>1.16</mu>
              <mu2>10</mu2>
              <fdir1>1 0 0</fdir1>
            </ode>
          </friction>
        </surface>
      </collision>
      <visual name="wheel_right_visual">
        <pose>0 0 -0.03 0 0 0</pose>
        <geometry>
          <mesh>
            <scale>0.98 0.98 1.0</scale>
            <uri>meshes/wheel/wheel.dae</uri>
          </mesh>
        </geometry>
      </visual>
    </link>
    <joint name="wheel_right_joint" type="revolute">
      <child>wheel_right</child>
      <parent>base_link</parent>
      <axis>
        <xyz>0 0 -1</xyz>
        <limit>
          <effort>9.6</effort>
        </limit>
        <dynamics>
          <damping>3.0</damping>
          <friction>0.5</friction>
        </dynamics>
      </axis>
    </joint>
    <plugin filename="gz-sim-diff-drive-system" name="gz::sim::systems::DiffDrive">
      <left_joint>wheel_left_joint</left_joint>
      <right_joint>wheel_right_joint</right_joint>
      <wheel_separation>0.514</wheel_separation>
      <wheel_radius>0.195</wheel_radius>
      <min_velocity>-10</min_velocity>
      <max_velocity>10</max_velocity>
      <min_acceleration>-0.5</min_acceleration>
      <max_acceleration>0.5</max_acceleration>
      <odom_publish_frequency>30</odom_publish_frequency>
      <topic>/cmd_vel</topic>
      <odom_topic>/odom</odom_topic>
      <tf_topic>/tf</tf_topic>
      <frame_id>odom</frame_id>
      <child_frame_id>base_link</child_frame_id>
    </plugin>
  </model>
</sdf>
